Workbook
Name DE: Sheet1!$C$12
Name DH: Sheet1!$C$10
Name DQ: Sheet1!$C$11
Name DS: Sheet1!$C$13
Name E: Sheet1!$C$8
Name H: Sheet1!$C$6
Name Q: Sheet1!$C$7
Name S: Sheet1!$C$9
Name W: Sheet1!$C$4

Sheet Macro1

Sheet DataList_EnemyA
A1: DataList
A2: No | B2: 音符の種類 | C2: 拍 | D2: 音階 | E2: 改行 | G2: 足すもの
A3: 1 | B3: 1 | C3: 3.2 | D3: 5 | F3: a
A4: 2 | B4: 1 | C4: =VLOOKUP(DataList_EnemyA!G4, Sheet1!$B$4:$C$13, 2, FALSE) +DataList_EnemyA!C3 -> 4.7 | D4: 6 | G4: H | H4: =VLOOKUP(G4, Sheet1!$B$4:$C$13, 2, FALSE) + C3 -> 4.7
A5: 3 | B5: 1 | C5: =VLOOKUP(DataList_EnemyA!G5, Sheet1!$B$4:$C$13, 2, FALSE) +DataList_EnemyA!C4 -> 5.825 | D5: 9 | G5: DQ | H5: =VLOOKUP(G5, Sheet1!$B$4:$C$13, 2, FALSE) + H4 -> 5.825
A6: 4 | B6: 1 | C6: =VLOOKUP(DataList_EnemyA!G6, Sheet1!$B$4:$C$13, 2, FALSE) +DataList_EnemyA!C5 -> 6.0125 | D6: 10 | G6: S | H6: =VLOOKUP(G6, Sheet1!$B$4:$C$13, 2, FALSE) + H5 -> 6.0125
A7: 5 | B7: 3 | C7: =VLOOKUP(DataList_EnemyA!G7, Sheet1!$B$4:$C$13, 2, FALSE) +DataList_EnemyA!C6 -> 6.3875 | D7: 0 | G7: E | H7: =VLOOKUP(G7, Sheet1!$B$4:$C$13, 2, FALSE) + H6 -> 6.3875
A8: 6 | B8: 1 | C8: =VLOOKUP(DataList_EnemyA!G8, Sheet1!$B$4:$C$13, 2, FALSE) +DataList_EnemyA!C7 -> 7.5125 | D8: 10 | G8: DQ | H8: =VLOOKUP(G8, Sheet1!$B$4:$C$13, 2, FALSE) + H7 -> 7.5125
A9: 7 | B9: 3 | C9: =VLOOKUP(DataList_EnemyA!G9, Sheet1!$B$4:$C$13, 2, FALSE) +DataList_EnemyA!C8 -> 7.8875 | D9: 0 | E9: 1 | F9: ae | G9: E | H9: =VLOOKUP(G9, Sheet1!$B$4:$C$13, 2, FALSE) + H8 -> 7.8875
A10: 8 | B10: 2 | C10: =VLOOKUP(DataList_EnemyA!G10, Sheet1!$B$4:$C$13, 2, FALSE) +DataList_EnemyA!C9 -> 9.3875 | D10: 5 | F10: a1 | G10: H | H10: =VLOOKUP(G10, Sheet1!$B$4:$C$13, 2, FALSE) + H9 -> 9.3875
A11: 9 | B11: 2 | C11: =VLOOKUP(DataList_EnemyA!G11, Sheet1!$B$4:$C$13, 2, FALSE) +DataList_EnemyA!C10 -> 10.1375 | D11: 9 | G11: Q | H11: =VLOOKUP(G11, Sheet1!$B$4:$C$13, 2, FALSE) + H10 -> 10.1375
A12: 10 | B12: 2 | C12: =VLOOKUP(DataList_EnemyA!G12, Sheet1!$B$4:$C$13, 2, FALSE) +DataList_EnemyA!C11 -> 10.5125 | D12: 10 | G12: E | H12: =VLOOKUP(G12, Sheet1!$B$4:$C$13, 2, FALSE) + H11 -> 10.5125
A13: 11 | B13: 3 | C13: =VLOOKUP(DataList_EnemyA!G13, Sheet1!$B$4:$C$13, 2, FALSE) +DataList_EnemyA!C12 -> 10.79375 | D13: 0 | G13: DS | H13: =VLOOKUP(G13, Sheet1!$B$4:$C$13, 2, FALSE) + H12 -> 10.79375
A14: 12 | B14: 3 | C14: =VLOOKUP(DataList_EnemyA!G14, Sheet1!$B$4:$C$13, 2, FALSE) +DataList_EnemyA!C13 -> 11.91875 | D14: 0 | G14: DQ | H14: =VLOOKUP(G14, Sheet1!$B$4:$C$13, 2, FALSE) + H13 -> 11.91875
A15: 13 | B15: 3 | C15: =VLOOKUP(DataList_EnemyA!G15, Sheet1!$B$4:$C$13, 2, FALSE) +DataList_EnemyA!C14 -> 12.2 | D15: 2 | G15: DS | H15: =VLOOKUP(G15, Sheet1!$B$4:$C$13, 2, FALSE) + H14 -> 12.2
A16: 14 | B16: 3 | C16: =VLOOKUP(DataList_EnemyA!G16, Sheet1!$B$4:$C$13, 2, FALSE) +DataList_EnemyA!C15 -> 12.48125 | D16: 3 | G16: DS | H16: =VLOOKUP(G16, Sheet1!$B$4:$C$13, 2, FALSE) + H15 -> 12.48125
A17: 15 | B17: 3 | C17: =VLOOKUP(DataList_EnemyA!G17, Sheet1!$B$4:$C$13, 2, FALSE) +DataList_EnemyA!C16 -> 13.04375 | D17: 2 | G17: DE | H17: =VLOOKUP(G17, Sheet1!$B$4:$C$13, 2, FALSE) + H16 -> 13.04375
A18: 16 | B18: 1 | C18: =VLOOKUP(DataList_EnemyA!G18, Sheet1!$B$4:$C$13, 2, FALSE) +DataList_EnemyA!C17 -> 13.79375 | D18: 10 | G18: Q | H18: =VLOOKUP(G18, Sheet1!$B$4:$C$13, 2, FALSE) + H17 -> 13.79375
A19: 17 | B19: 2 | C19: =VLOOKUP(DataList_EnemyA!G19, Sheet1!$B$4:$C$13, 2, FALSE) +DataList_EnemyA!C18 -> 14.54375 | D19: 5 | E19: 1 | F19: ae | G19: Q | H19: =VLOOKUP(G19, Sheet1!$B$4:$C$13, 2, FALSE) + H18 -> 14.54375
A20: 18 | B20: 3 | C20: =VLOOKUP(DataList_EnemyA!G20, Sheet1!$B$4:$C$13, 2, FALSE) +DataList_EnemyA!C19 -> 15.29375 | D20: 2 | F20: a2 | G20: Q | H20: =VLOOKUP(G20, Sheet1!$B$4:$C$13, 2, FALSE) + H19 -> 15.29375
A21: 19 | B21: 3 | C21: =VLOOKUP(DataList_EnemyA!G21, Sheet1!$B$4:$C$13, 2, FALSE) +DataList_EnemyA!C20 -> 16.79375 | D21: 0 | G21: H | H21: =VLOOKUP(G21, Sheet1!$B$4:$C$13, 2, FALSE) + H20 -> 16.79375
A22: 20 | B22: 3 | C22: =VLOOKUP(DataList_EnemyA!G22, Sheet1!$B$4:$C$13, 2, FALSE) +DataList_EnemyA!C21 -> 18.29375 | D22: 0 | G22: H | H22: =VLOOKUP(G22, Sheet1!$B$4:$C$13, 2, FALSE) + H21 -> 18.29375
A23: 21 | B23: 3 | C23: =VLOOKUP(DataList_EnemyA!G23, Sheet1!$B$4:$C$13, 2, FALSE) +DataList_EnemyA!C22 -> 18.66875 | D23: 2 | G23: E | H23: =VLOOKUP(G23, Sheet1!$B$4:$C$13, 2, FALSE) + H22 -> 18.66875
A24: 22 | B24: 3 | C24: =VLOOKUP(DataList_EnemyA!G24, Sheet1!$B$4:$C$13, 2, FALSE) +DataList_EnemyA!C23 -> 19.04375 | D24: 5 | G24: E | H24: =VLOOKUP(G24, Sheet1!$B$4:$C$13, 2, FALSE) + H23 -> 19.04375
A25: 23 | B25: 3 | C25: =VLOOKUP(DataList_EnemyA!G25, Sheet1!$B$4:$C$13, 2, FALSE) +DataList_EnemyA!C24 -> 19.41875 | D25: 2 | G25: E | H25: =VLOOKUP(G25, Sheet1!$B$4:$C$13, 2, FALSE) + H24 -> 19.41875
A26: 24 | B26: 2 | C26: =VLOOKUP(DataList_EnemyA!G26, Sheet1!$B$4:$C$13, 2, FALSE) +DataList_EnemyA!C25 -> 19.98125 | D26: 10 | G26: DE | H26: =VLOOKUP(G26, Sheet1!$B$4:$C$13, 2, FALSE) + H25 -> 19.98125
A27: 25 | B27: 3 | C27: =VLOOKUP(DataList_EnemyA!G27, Sheet1!$B$4:$C$13, 2, FALSE) +DataList_EnemyA!C26 -> 21.10625 | D27: 5 | F27: a3 | G27: DQ | H27: =VLOOKUP(G27, Sheet1!$B$4:$C$13, 2, FALSE) + H26 -> 21.10625
A28: 26 | B28: 3 | C28: =VLOOKUP(DataList_EnemyA!G28, Sheet1!$B$4:$C$13, 2, FALSE) +DataList_EnemyA!C27 -> 21.48125 | D28: 2 | E28: 1 | G28: E | H28: =VLOOKUP(G28, Sheet1!$B$4:$C$13, 2, FALSE) + H27 -> 21.48125
A29: 27 | B29: 3 | C29: =VLOOKUP(DataList_EnemyA!G29, Sheet1!$B$4:$C$13, 2, FALSE) +DataList_EnemyA!C28 -> 22.23125 | D29: 0 | G29: Q | H29: =VLOOKUP(G29, Sheet1!$B$4:$C$13, 2, FALSE) + H28 -> 22.23125
A30: 28 | B30: 3 | C30: =VLOOKUP(DataList_EnemyA!G30, Sheet1!$B$4:$C$13, 2, FALSE) +DataList_EnemyA!C29 -> 22.79375 | D30: 2 | E30: 1 | G30: DE | H30: =VLOOKUP(G30, Sheet1!$B$4:$C$13, 2, FALSE) + H29 -> 22.79375
A31: 29 | B31: 2 | C31: =VLOOKUP(DataList_EnemyA!G31, Sheet1!$B$4:$C$13, 2, FALSE) +DataList_EnemyA!C30 -> 24.29375 | D31: 9 | F31: a4 | G31: H | H31: =VLOOKUP(G31, Sheet1!$B$4:$C$13, 2, FALSE) + H30 -> 24.29375
A32: 30 | B32: 2 | C32: =VLOOKUP(DataList_EnemyA!G32, Sheet1!$B$4:$C$13, 2, FALSE) +DataList_EnemyA!C31 -> 24.66875 | D32: 10 | G32: E | H32: =VLOOKUP(G32, Sheet1!$B$4:$C$13, 2, FALSE) + H31 -> 24.66875
A33: 31 | B33: 3 | C33: =VLOOKUP(DataList_EnemyA!G33, Sheet1!$B$4:$C$13, 2, FALSE) +DataList_EnemyA!C32 -> 25.04375 | D33: 0 | G33: E | H33: =VLOOKUP(G33, Sheet1!$B$4:$C$13, 2, FALSE) + H32 -> 25.04375
A34: 32 | B34: 3 | C34: =VLOOKUP(DataList_EnemyA!G34, Sheet1!$B$4:$C$13, 2, FALSE) +DataList_EnemyA!C33 -> 25.41875 | D34: 5 | G34: E | H34: =VLOOKUP(G34, Sheet1!$B$4:$C$13, 2, FALSE) + H33 -> 25.41875
A35: 33 | B35: 3 | C35: =VLOOKUP(DataList_EnemyA!G35, Sheet1!$B$4:$C$13, 2, FALSE) +DataList_EnemyA!C34 -> 25.79375 | D35: 7 | G35: E | H35: =VLOOKUP(G35, Sheet1!$B$4:$C$13, 2, FALSE) + H34 -> 25.79375
A36: 34 | B36: 3 | C36: =VLOOKUP(DataList_EnemyA!G36, Sheet1!$B$4:$C$13, 2, FALSE) +DataList_EnemyA!C35 -> 25.98125 | D36: 7 | G36: S | H36: =VLOOKUP(G36, Sheet1!$B$4:$C$13, 2, FALSE) + H35 -> 25.98125
A37: 35 | B37: 3 | C37: =VLOOKUP(DataList_EnemyA!G37, Sheet1!$B$4:$C$13, 2, FALSE) +DataList_EnemyA!C36 -> 26.16875 | D37: 5 | G37: S | H37: =VLOOKUP(G37, Sheet1!$B$4:$C$13, 2, FALSE) + H36 -> 26.16875
A38: 36 | B38: 3 | C38: =VLOOKUP(DataList_EnemyA!G38, Sheet1!$B$4:$C$13, 2, FALSE) +DataList_EnemyA!C37 -> 26.54375 | D38: 2 | G38: E | H38: =VLOOKUP(G38, Sheet1!$B$4:$C$13, 2, FALSE) + H37 -> 26.54375
A39: 37 | B39: 3 | C39: =VLOOKUP(DataList_EnemyA!G39, Sheet1!$B$4:$C$13, 2, FALSE) +DataList_EnemyA!C38 -> 26.91875 | D39: 0 | G39: E | H39: =VLOOKUP(G39, Sheet1!$B$4:$C$13, 2, FALSE) + H38 -> 26.91875
A40: 38 | B40: 3 | C40: =VLOOKUP(DataList_EnemyA!G40, Sheet1!$B$4:$C$13, 2, FALSE) +DataList_EnemyA!C39 -> 27.48125 | D40: 2 | F40: a5 | G40: DE | H40: =VLOOKUP(G40, Sheet1!$B$4:$C$13, 2, FALSE) + H39 -> 27.48125
...

Sheet Sheet1
A2: BMP | C2: 80
A4: 全音符(W) | B4: W | C4: =C7*4 -> 3
A6: ２分音符（H） | B6: H | C6: =C7*2 -> 1.5
A7: ４分音符（Q） | B7: Q | C7: =SUM(60/C2) -> 0.75
A8: ８分音符（E） | B8: E | C8: =C7*0.5 -> 0.375
A9: １６分音符（S) | B9: S | C9: =C7*0.25 -> 0.1875
A10: フ点２分音符（DH） | B10: DH | C10: =SUM(C7*3) -> 2.25
A11: フ点４分音符（DQ） | B11: DQ | C11: =C7*1.5 -> 1.125
A12: フ点８分音符（DE） | B12: DE | C12: =C7*0.75 -> 0.5625
A13: フ点１６分音符（DS） | B13: DS | C13: =C7*0.375 -> 0.28125
A15: C | C15: 0
A16: Cs | C16: 1
A17: D | C17: 2
A18: Ds | C18: 3
A19: E | C19: 4
A20: F | C20: 5
A21: Fs | C21: 6
A22: G | C22: 7
A23: Gs | C23: 8
A24: A | C24: 9
A25: As | C25: 10
A26: B | C26: 11

Sheet enemya_list
A1: 1 | B1: 3.7 | C1: 5
A2: 1 | B2: =B1+H -> 5.2 | C2: 6
A3: 1 | B3: =B2+Q -> 5.95 | C3: 9
A4: 1 | B4: =B3+S -> 6.1375 | C4: 10
A5: 3 | B5: =B4+S -> 6.325 | C5: 0
A6: 1 | B6: =B5+DQ -> 7.45 | C6: 10
A7: 3 | B7: =B6+E -> 7.825 | C7: 0
A8: 2 | B8: =B7+H -> 9.325 | C8: 5
A9: 2 | B9: =B8+Q -> 10.075 | C9: 9
A10: 2 | B10: =B9+E -> 10.45 | C10: 10
A11: 3 | B11: =B10+E -> 10.825 | C11: 0
A12: 3 | B12: =B11+DQ -> 11.95 | C12: 0
A13: 3 | B13: =B12+DS -> 12.23125 | C13: 2
A14: 3 | B14: =B13+DS -> 12.5125 | C14: 3
A15: 3 | B15: =B14+DE -> 13.075 | C15: 2
A16: 1 | B16: =B15+Q -> 13.825 | C16: 10
A17: 2 | B17: =B16+Q -> 14.575 | C17: 5
A18: 3 | B18: =B17+Q -> 15.325 | C18: 2
A19: 3 | B19: =B18+H -> 16.825 | C19: 1
A20: 3 | B20: =B19+H -> 18.325 | C20: 1
A21: 3 | B21: =B20+E -> 18.7 | C21: 2
A22: 3 | B22: =B21+E -> 19.075 | C22: 5
A23: 3 | B23: =B22+E -> 19.45 | C23: 2
A24: 2 | B24: =B23+DE -> 20.0125 | C24: 10
A25: 3 | B25: =B24+DQ -> 21.1375 | C25: 5
A26: 3 | B26: =B25+E -> 21.5125 | C26: 2
A27: 3 | B27: =B26+DQ -> 22.6375 | C27: 0
A28: 3 | B28: =B27+E -> 23.0125 | C28: 2
A29: 2 | B29: =B28+H -> 24.5125 | C29: 9
A30: 2 | B30: =B29+E -> 24.8875 | C30: 10
A31: 3 | B31: =B30+E -> 25.2625 | C31: 0
A32: 3 | B32: =B31+E -> 25.6375 | C32: 5
A33: 3 | B33: =B32+E -> 26.0125 | C33: 7
A34: 3 | B34: =B33+S -> 26.2 | C34: 7
A35: 3 | B35: =B34+S -> 26.3875 | C35: 5
A36: 3 | B36: =B35+E -> 26.7625 | C36: 2
A37: 3 | B37: =B36+E -> 27.1375 | C37: 0
A38: 3 | B38: =B37+DE -> 27.7 | C38: 2
A39: 2 | B39: =B38+DE -> 28.2625 | C39: 9
A40: 1 | B40: =B39+E -> 28.6375 | C40: 10
...
