Workbook
Name DE: Sheet1!$C$12
Name DH: Sheet1!$C$10
Name DQ: Sheet1!$C$11
Name DS: Sheet1!$C$13
Name E: Sheet1!$C$8
Name H: Sheet1!$C$6
Name Q: Sheet1!$C$7
Name S: Sheet1!$C$9
Name W: Sheet1!$C$4

Sheet Macro1

Sheet DataList_EnemyA
A1: DataList
A2: No | B2: 音符の種類 | C2: 拍 | D2: 音階 | E2: 改行 | G2: 足すもの | H2: 休符
A3: 1 | B3: 1 | C3: 1 | D3: 1
A4: 2 | B4: 1 | C4: =VLOOKUP(DataList_EnemyA!G4, Sheet1!$B$4:$C$13, 2, FALSE) +DataList_EnemyA!C3 -> 1.3797468 | D4: 1 | G4: Q
A5: 3 | B5: 1 | C5: =VLOOKUP(DataList_EnemyA!G5, Sheet1!$B$4:$C$13, 2, FALSE) +DataList_EnemyA!C4 -> 1.7594937 | D5: 3 | G5: Q | H5: E
A6: 4 | B6: 1 | C6: =VLOOKUP(DataList_EnemyA!G6, Sheet1!$B$4:$C$13, 2, FALSE) +DataList_EnemyA!C5 -> 2.1392405 | D6: 1 | G6: Q
A7: 5 | B7: 1 | C7: =VLOOKUP(DataList_EnemyA!G7, Sheet1!$B$4:$C$13, 2, FALSE) +DataList_EnemyA!C6 -> 2.3291139 | D7: 0 | G7: E
A8: 6 | B8: 1 | C8: =VLOOKUP(DataList_EnemyA!G8, Sheet1!$B$4:$C$13, 2, FALSE) +DataList_EnemyA!C7 -> 2.5189873 | D8: 1 | G8: E
A9: 7 | B9: 1 | C9: =VLOOKUP(DataList_EnemyA!G9, Sheet1!$B$4:$C$13, 2, FALSE) +DataList_EnemyA!C8 -> 2.7088608 | D9: 3 | G9: E
A10: 8 | B10: 2 | C10: =VLOOKUP(DataList_EnemyA!G10, Sheet1!$B$4:$C$13, 2, FALSE) +DataList_EnemyA!C9 -> 3.0886076 | D10: 1 | F10: a1e | G10: Q
A11: 9 | B11: 2 | C11: =VLOOKUP(DataList_EnemyA!G11, Sheet1!$B$4:$C$13, 2, FALSE) +DataList_EnemyA!C10 -> 3.8481013 | D11: 1 | F11: a2 | G11: H
A12: 10 | B12: 2 | C12: =VLOOKUP(DataList_EnemyA!G12, Sheet1!$B$4:$C$13, 2, FALSE) +DataList_EnemyA!C11 -> 4.2278481 | D12: 1 | G12: Q
A13: 11 | B13: 2 | C13: =VLOOKUP(DataList_EnemyA!G13, Sheet1!$B$4:$C$13, 2, FALSE) +DataList_EnemyA!C12 -> 4.6075949 | D13: 3 | G13: Q
A14: 12 | B14: 2 | C14: =VLOOKUP(DataList_EnemyA!G14, Sheet1!$B$4:$C$13, 2, FALSE) +DataList_EnemyA!C13 -> 4.9873418 | D14: 1 | G14: Q
A15: 13 | B15: 2 | C15: =VLOOKUP(DataList_EnemyA!G15, Sheet1!$B$4:$C$13, 2, FALSE) +DataList_EnemyA!C14 -> 5.3670886 | D15: 0 | G15: Q
A16: 14 | B16: 2 | C16: =VLOOKUP(DataList_EnemyA!G16, Sheet1!$B$4:$C$13, 2, FALSE) +DataList_EnemyA!C15 -> 5.556962 | D16: 1 | F16: a3 | G16: E
A17: 15 | B17: 2 | C17: =VLOOKUP(DataList_EnemyA!G17, Sheet1!$B$4:$C$13, 2, FALSE) +DataList_EnemyA!C16 -> 5.7468354 | D17: 3 | G17: E
A18: 16 | B18: 2 | C18: =VLOOKUP(DataList_EnemyA!G18, Sheet1!$B$4:$C$13, 2, FALSE) +DataList_EnemyA!C17 -> 5.9367089 | D18: 5 | G18: E
A19: 17 | B19: 2 | C19: =VLOOKUP(DataList_EnemyA!G19, Sheet1!$B$4:$C$13, 2, FALSE) +DataList_EnemyA!C18 -> 6.1265823 | D19: 6 | G19: E
A20: 18 | B20: 2 | C20: =VLOOKUP(DataList_EnemyA!G20, Sheet1!$B$4:$C$13, 2, FALSE) +DataList_EnemyA!C19 -> 6.3164557 | D20: 5 | G20: E
A21: 19 | B21: 1 | C21: =VLOOKUP(DataList_EnemyA!G21, Sheet1!$B$4:$C$13, 2, FALSE) +DataList_EnemyA!C20 -> 6.5063291 | D21: 3 | G21: E
A22: 20 | B22: 2 | C22: =VLOOKUP(DataList_EnemyA!G22, Sheet1!$B$4:$C$13, 2, FALSE) +DataList_EnemyA!C21 -> 6.6962025 | D22: 1 | F22: a3 | G22: E
A23: 21 | B23: 1 | C23: =VLOOKUP(DataList_EnemyA!G23, Sheet1!$B$4:$C$13, 2, FALSE) +DataList_EnemyA!C22 -> 7.0759494 | D23: 1 | G23: Q
A24: 22 | B24: 2 | C24: =VLOOKUP(DataList_EnemyA!G24, Sheet1!$B$4:$C$13, 2, FALSE) +DataList_EnemyA!C23 -> 7.4556962 | D24: 3 | G24: Q
A25: 23 | B25: 1 | C25: =VLOOKUP(DataList_EnemyA!G25, Sheet1!$B$4:$C$13, 2, FALSE) +DataList_EnemyA!C24 -> 7.6455696 | D25: 1 | G25: E
A26: 24 | B26: 2 | C26: =C25 + VLOOKUP(G26, Sheet1!$B$4:$C$13, 2, FALSE) + IF(H26="", 0, VLOOKUP(H26, Sheet1!$B$4:$C$13, 2, FALSE)) -> 8.0253165 | D26: 0 | G26: E | H26: E
A27: 25 | B27: 1 | C27: =C26 + VLOOKUP(G27, Sheet1!$B$4:$C$13, 2, FALSE) + IF(H27="", 0, VLOOKUP(H27, Sheet1!$B$4:$C$13, 2, FALSE)) -> 8.5949367 | D27: 1 | G27: Q | H27: E
A28: 26 | B28: 2 | C28: =C27 + VLOOKUP(G28, Sheet1!$B$4:$C$13, 2, FALSE) + IF(H28="", 0, VLOOKUP(H28, Sheet1!$B$4:$C$13, 2, FALSE)) -> 8.9746835 | D28: 3 | F28: a3e | G28: Q
A29: 27 | B29: 2 | C29: =C28 + VLOOKUP(G29, Sheet1!$B$4:$C$13, 2, FALSE) + IF(H29="", 0, VLOOKUP(H29, Sheet1!$B$4:$C$13, 2, FALSE)) -> 9.3544304 | D29: 3 | G29: Q
A30: 28 | B30: 1 | C30: =C29 + VLOOKUP(G30, Sheet1!$B$4:$C$13, 2, FALSE) + IF(H30="", 0, VLOOKUP(H30, Sheet1!$B$4:$C$13, 2, FALSE)) -> 10.113924 | D30: 1 | F30: 歌はじめ | G30: H
A31: 29 | B31: 1 | C31: =C30 + VLOOKUP(G31, Sheet1!$B$4:$C$13, 2, FALSE) + IF(H31="", 0, VLOOKUP(H31, Sheet1!$B$4:$C$13, 2, FALSE)) -> 10.683544 | D31: 1 | G31: DQ
A32: 30 | B32: 1 | C32: =C31 + VLOOKUP(G32, Sheet1!$B$4:$C$13, 2, FALSE) + IF(H32="", 0, VLOOKUP(H32, Sheet1!$B$4:$C$13, 2, FALSE)) -> 10.873418 | D32: 1 | G32: E
A33: 31 | B33: 1 | C33: =C32 + VLOOKUP(G33, Sheet1!$B$4:$C$13, 2, FALSE) + IF(H33="", 0, VLOOKUP(H33, Sheet1!$B$4:$C$13, 2, FALSE)) -> 11.443038 | D33: 1 | G33: DQ
A34: 32 | B34: 1 | C34: =C33 + VLOOKUP(G34, Sheet1!$B$4:$C$13, 2, FALSE) + IF(H34="", 0, VLOOKUP(H34, Sheet1!$B$4:$C$13, 2, FALSE)) -> 11.632911 | D34: 1 | G34: E
A35: 33 | B35: 2 | C35: =C34 + VLOOKUP(G35, Sheet1!$B$4:$C$13, 2, FALSE) + IF(H35="", 0, VLOOKUP(H35, Sheet1!$B$4:$C$13, 2, FALSE)) -> 11.822785 | D35: 3 | G35: E
A36: 34 | B36: 2 | C36: =C35 + VLOOKUP(G36, Sheet1!$B$4:$C$13, 2, FALSE) + IF(H36="", 0, VLOOKUP(H36, Sheet1!$B$4:$C$13, 2, FALSE)) -> 12.012658 | D36: 5 | G36: E
A37: 35 | B37: 2 | C37: =C36 + VLOOKUP(G37, Sheet1!$B$4:$C$13, 2, FALSE) + IF(H37="", 0, VLOOKUP(H37, Sheet1!$B$4:$C$13, 2, FALSE)) -> 12.202532 | D37: 7 | G37: E
A38: 36 | B38: 2 | C38: =C37 + VLOOKUP(G38, Sheet1!$B$4:$C$13, 2, FALSE) + IF(H38="", 0, VLOOKUP(H38, Sheet1!$B$4:$C$13, 2, FALSE)) -> 12.392405 | D38: 5 | G38: E
A39: 37 | B39: 2 | C39: =C38 + VLOOKUP(G39, Sheet1!$B$4:$C$13, 2, FALSE) + IF(H39="", 0, VLOOKUP(H39, Sheet1!$B$4:$C$13, 2, FALSE)) -> 12.962025 | D39: 1 | F39: あ４ | G39: DQ
A40: 38 | B40: 1 | C40: =C39 + VLOOKUP(G40, Sheet1!$B$4:$C$13, 2, FALSE) + IF(H40="", 0, VLOOKUP(H40, Sheet1!$B$4:$C$13, 2, FALSE)) -> 13.151899 | D40: 3 | G40: E
...

Sheet Sheet1
A2: BMP | C2: 158 | D2: 150
A4: 全音符(W) | B4: W | C4: =C7*4 -> 1.5189873
A6: ２分音符（H） | B6: H | C6: =C7*2 -> 0.75949367
A7: ４分音符（Q） | B7: Q | C7: =SUM(60/C2) -> 0.37974684
A8: ８分音符（E） | B8: E | C8: =C7*0.5 -> 0.18987342
A9: １６分音符（S) | B9: S | C9: =C7*0.25 -> 0.094936709
A10: フ点２分音符（DH） | B10: DH | C10: =SUM(C7*3) -> 1.1392405
A11: フ点４分音符（DQ） | B11: DQ | C11: =C7*1.5 -> 0.56962025
A12: フ点８分音符（DE） | B12: DE | C12: =C7*0.75 -> 0.28481013
A13: フ点１６分音符（DS） | B13: DS | C13: =C7*0.375 -> 0.14240506

Sheet enemya_list
A1: 1 | B1: =DataList_EnemyA!C3 -> 1 | C1: 1
A2: 1 | B2: =DataList_EnemyA!C4 -> 1.3797468 | C2: 1
A3: 1 | B3: =DataList_EnemyA!C5 -> 1.7594937 | C3: 3
A4: 1 | B4: =DataList_EnemyA!C6 -> 2.1392405 | C4: 1
A5: 1 | B5: =DataList_EnemyA!C7 -> 2.3291139 | C5: 0
A6: 1 | B6: =DataList_EnemyA!C8 -> 2.5189873 | C6: 1
A7: 1 | B7: =DataList_EnemyA!C9 -> 2.7088608 | C7: 3
A8: 2 | B8: =DataList_EnemyA!C10 -> 3.0886076 | C8: 1
A9: 2 | B9: =DataList_EnemyA!C11 -> 3.8481013 | C9: 1
A10: 2 | B10: =DataList_EnemyA!C12 -> 4.2278481 | C10: 1
A11: 2 | B11: =DataList_EnemyA!C13 -> 4.6075949 | C11: 3
A12: 2 | B12: =DataList_EnemyA!C14 -> 4.9873418 | C12: 1
... A182: 3 | B182: =DataList_EnemyA!C184 -> 62.803797 | C182: 1
A183: 0 | B183: =DataList_EnemyA!C187 -> 66.221519 | C183: 11
A184: 0 | B184: =DataList_EnemyA!C188 -> 66.411392 | C184: 11
A185: 0 | B185: =DataList_EnemyA!C189 -> 66.601266 | C185: 11
A186: 0 | B186: =DataList_EnemyA!C190 -> 66.791139 | C186: 11
A187: 0 | B187: =DataList_EnemyA!C191 -> 66.981013 | C187: 4
A188: 0 | B188: =DataList_EnemyA!C192 -> 67.170886 | C188: 3
A189: 0 | B189: =DataList_EnemyA!C193 -> 67.360759 | C189: 4
A190: 1 | B190: =DataList_EnemyA!C194 -> 69.259494 | C190: 11
A191: 1 | B191: =DataList_EnemyA!C195 -> 69.449367 | C191: 11
A192: 1 | B192: =DataList_EnemyA!C196 -> 69.639241 | C192: 11
A193: 1 | B193: =DataList_EnemyA!C197 -> 69.829114 | C193: 11
A194: 1 | B194: =DataList_EnemyA!C198 -> 70.018987 | C194: 4
... A198: 1 | B198: =DataList_EnemyA!C202 -> 71.917722 | C198: 8
A199: 1 | B199: =DataList_EnemyA!C204 -> 74.955696 | C199: 10
A200: 2 | B200: =DataList_EnemyA!C205 -> 75.14557 | C200: 6
A201: 1 | B201: =DataList_EnemyA!C206 -> 75.525316 | C201: 5
A202: 2 | B202: =DataList_EnemyA!C207 -> 75.905063 | C202: 3
A203: 1 | B203: =DataList_EnemyA!C208 -> 76.28481 | C203: 0
A204: 2 | B204: =DataList_EnemyA!C209 -> 76.85443 | C204: 1
A205: 1 | B205: =DataList_EnemyA!C210 -> 77.234177 | C205: 3
A206: 1 | B206: =DataList_EnemyA!C211 -> 77.803797 | C206: 1
A207: 2 | B207: =DataList_EnemyA!C212 -> 78.563291 | C207: 0
A208: 2 | B208: =DataList_EnemyA!C213 -> 79.322785 | C208: 1
