Workbook

Sheet BGM3
A1: DataList
A2: No | B2: 出現時間 | C2: x座標 | D2: y座標
A3: 1 | B3: 2 | C3: 0.9 | D3: 11
A4: 2 | B4: 3 | C4: =C3+(Sheet1!B2-Sheet1!B1) -> 1.3802039 | D4: 2 | H4: =C4-C3 -> 0.4802039
A5: 3 | B5: 3 | C5: =C4+(Sheet1!B3-Sheet1!B2) -> 1.5000039 | D5: 6
A6: 4 | B6: 3 | C6: =C5+(Sheet1!B4-Sheet1!B3) -> 1.6203139 | D6: 7
A7: 5 | B7: 3 | C7: =C6+(Sheet1!B5-Sheet1!B4) -> 1.7802039 | D7: 6
A8: 6 | B8: 3 | C8: =C7+(Sheet1!B6-Sheet1!B5) -> 1.9000039 | D8: 2
A9: 7 | B9: 1 | C9: =C8+(Sheet1!B7-Sheet1!B6) -> 2.1802039 | D9: 11
A10: 8 | B10: 1 | C10: =C9+(Sheet1!B8-Sheet1!B7) -> 2.3401039 | D10: 9
A11: 9 | B11: 1 | C11: =C10+(Sheet1!B9-Sheet1!B8) -> 2.7000039 | D11: 11
A12: 10 | B12: 3 | C12: =C11+(Sheet1!B10-Sheet1!B9) -> 3.9000039 | D12: 7 | G12: a2
A13: 11 | B13: 3 | C13: =C12+(Sheet1!B11-Sheet1!B10) -> 4.1802039 | D13: 2
A14: 12 | B14: 3 | C14: =C13+(Sheet1!B12-Sheet1!B11) -> 4.5401039 | D14: 0
A15: 13 | B15: 3 | C15: =C14+(Sheet1!B13-Sheet1!B12) -> 4.6203139 | D15: 2
A16: 14 | B16: 3 | C16: =C15+(Sheet1!B14-Sheet1!B13) -> 4.8203139 | D16: 0
A17: 15 | B17: 2 | C17: =C16+(Sheet1!B15-Sheet1!B14) -> 4.9401039 | D17: 11
B18: 2 | C18: =C17+(Sheet1!B16-Sheet1!B15) -> 5.1802039 | D18: 9
B19: 2 | C19: =C18+(Sheet1!B17-Sheet1!B16) -> 5.3000039 | D19: 9
B20: 2 | C20: =C19+(Sheet1!B18-Sheet1!B17) -> 5.4203139 | D20: 4
B21: 2 | C21: =C20+(Sheet1!B19-Sheet1!B18) -> 5.7000039 | D21: 7
B22: 2 | C22: =C21+(Sheet1!B20-Sheet1!B19) -> 6.8598939 | D22: 11 | F22: a3
B23: 3 | C23: =C22+(Sheet1!B21-Sheet1!B20) -> 7.1802039 | D23: 7
B24: 3 | C24: =C23+(Sheet1!B22-Sheet1!B21) -> 7.3802039 | D24: 2
B25: 3 | C25: =C24+(Sheet1!B23-Sheet1!B22) -> 7.6203139 | D25: 7
B26: 3 | C26: =C25+(Sheet1!B24-Sheet1!B23) -> 7.8203139 | D26: 6
B27: 3 | C27: =C26+(Sheet1!B25-Sheet1!B24) -> 7.9401039 | D27: 4
B28: 3 | C28: =C27+(Sheet1!B26-Sheet1!B25) -> 8.1802039 | D28: 2
B29: 3 | C29: =C28+(Sheet1!B27-Sheet1!B26) -> 8.3401039 | D29: 2
B30: 2 | C30: =C29+(Sheet1!B28-Sheet1!B27) -> 8.7401039 | D30: 11
B31: 3 | C31: =C30+(Sheet1!B29-Sheet1!B28) -> 9.7802039 | D31: 0 | F31: a4
B32: 2 | C32: =C31+(Sheet1!B30-Sheet1!B29) -> 9.8598939 | D32: 7
B33: 2 | C33: =C32+(Sheet1!B31-Sheet1!B30) -> 10.380204 | D33: 7
B34: 3 | C34: =C33+(Sheet1!B32-Sheet1!B31) -> 10.540104 | D34: 2
B35: 2 | C35: =C34+(Sheet1!B33-Sheet1!B32) -> 10.820304 | D35: 10
B36: 1 | C36: =C35+(Sheet1!B34-Sheet1!B33) -> 10.900004 | D36: 9
B37: 1 | C37: =C36+(Sheet1!B35-Sheet1!B34) -> 11.180204 | D37: 7
B38: 1 | C38: =C37+(Sheet1!B36-Sheet1!B35) -> 11.380204 | D38: 6
B39: 3 | C39: =C38+(Sheet1!B37-Sheet1!B36) -> 12.780204 | D39: 7 | F39: a5
B40: 3 | C40: =C39+(Sheet1!B38-Sheet1!B37) -> 13.259904 | D40: 9
...

Sheet Sheet1
A1: 0.8598961 | B1: 1.2
A2: 1.3401 | B2: 1.6802039 | D2: =A2-A1 -> 0.4802039
A3: 1.4599 | B3: 1.8000039
A4: 1.58021 | B4: 1.9203139
A5: 1.7401 | B5: 2.0802039
A6: 1.8599 | B6: 2.2000039
A7: 2.1401 | B7: 2.4802039
A8: 2.3 | B8: 2.6401039
A9: 2.6599 | B9: 3.0000039
A10: 3.8599 | B10: 4.2000039
A11: 4.1401 | B11: 4.4802039
A12: 4.5 | B12: 4.8401039
A13: 4.58021 | B13: 4.9203139
A14: 4.78021 | B14: 5.1203139
... A455: 143.201 | B455: 145.0599
A456: 144.36
A457: 144.88
A458: 145.04
A459: 145.12
A460: 145.28
A461: 145.44
A462: 145.68
A463: 145.76
A464: 145.84
A465: 146.24
A466: 147.28
A467: 147.32
... A476: 148.84

Sheet BGM3CSV
A1: 2 | B1: ='BGM3'!C3 -> 0.9 | C1: 11
A2: 3 | B2: ='BGM3'!C4 -> 1.3802039 | C2: 2
A3: 3 | B3: ='BGM3'!C5 -> 1.5000039 | C3: 6
A4: 3 | B4: ='BGM3'!C6 -> 1.6203139 | C4: 7
A5: 3 | B5: ='BGM3'!C7 -> 1.7802039 | C5: 6
A6: 3 | B6: ='BGM3'!C8 -> 1.9000039 | C6: 2
A7: 1 | B7: ='BGM3'!C9 -> 2.1802039 | C7: 11
A8: 1 | B8: ='BGM3'!C10 -> 2.3401039 | C8: 9
A9: 1 | B9: ='BGM3'!C11 -> 2.7000039 | C9: 11
A10: 3 | B10: ='BGM3'!C12 -> 3.9000039 | C10: 7
A11: 3 | B11: ='BGM3'!C13 -> 4.1802039 | C11: 2
A12: 3 | B12: ='BGM3'!C14 -> 4.5401039 | C12: 0
... A455: 2 | B455: ='BGM3'!C457 -> 144.7599 | C455: 7
